<mujoco model="widowGo1">
  <default>
    <default class="robot">
      <default class="motor">
        <joint />
        <motor />
      </default>
      <default class="visual">
        <geom material="visualgeom" contype="0" conaffinity="0" group="2" />
      </default>
      <default class="collision">
        <geom material="collision_material" condim="3" contype="0" conaffinity="1" priority="1" group="1" solref="0.005 1" solimp="0.99 0.999 1e-05" friction="1 0.01 0.01" />
      </default>
    </default>
  </default>

  <compiler angle="radian" />

  <asset>
    <material name="black" rgba="0.0 0.0 0.0 1.0" />
    <material name="blue" rgba="0.0 0.0 0.8 1.0" />
    <material name="green" rgba="0.0 0.8 0.0 1.0" />
    <material name="grey" rgba="0.2 0.2 0.2 1.0" />
    <material name="silver" rgba="0.913725490196 0.913725490196 0.847058823529 1.0" />
    <material name="orange" rgba="1.0 0.423529411765 0.0392156862745 1.0" />
    <material name="brown" rgba="0.870588235294 0.811764705882 0.764705882353 1.0" />
    <material name="red" rgba="0.8 0.0 0.0 1.0" />
    <material name="white" rgba="1.0 1.0 1.0 1.0" />
    <material name="default_material" rgba="0.7 0.7 0.7 1" />
    <material name="collision_material" rgba="1.0 0.28 0.1 0.9" />
    <mesh name="wx250s_1_base" file="../meshes/wx250s_meshes/wx250s_1_base.stl" scale="0.001 0.001 0.001" />
    <mesh name="wx250s_2_shoulder" file="../meshes/wx250s_meshes/wx250s_2_shoulder.stl" scale="0.001 0.001 0.001" />
    <mesh name="wx250s_3_upper_arm" file="../meshes/wx250s_meshes/wx250s_3_upper_arm.stl" scale="0.001 0.001 0.001" />
    <mesh name="wx250s_4_upper_forearm" file="../meshes/wx250s_meshes/wx250s_4_upper_forearm.stl" scale="0.001 0.001 0.001" />
    <mesh name="wx250s_5_lower_forearm" file="../meshes/wx250s_meshes/wx250s_5_lower_forearm.stl" scale="0.001 0.001 0.001" />
    <mesh name="wx250s_6_wrist" file="../meshes/wx250s_meshes/wx250s_6_wrist.stl" scale="0.001 0.001 0.001" />
    <mesh name="wx250s_7_gripper" file="../meshes/wx250s_meshes/wx250s_7_gripper.stl" scale="0.001 0.001 0.001" />
    <mesh name="wx250s_8_gripper_prop" file="../meshes/wx250s_meshes/wx250s_8_gripper_prop.stl" scale="0.001 0.001 0.001" />
    <mesh name="wx250s_9_gripper_bar" file="../meshes/wx250s_meshes/wx250s_9_gripper_bar.stl" scale="0.001 0.001 0.001" />
    <mesh name="wx250s_10_gripper_finger" file="../meshes/wx250s_meshes/wx250s_10_gripper_finger.stl" scale="0.001 0.001 0.001" />
    <mesh name="trunk" file="../meshes/trunk.stl" scale="0.001 0.001 0.001" />
    <mesh name="hip" file="../meshes/hip.stl" scale="0.001 0.001 0.001" />
    <mesh name="thigh_mirror" file="../meshes/thigh_mirror.stl" scale="0.001 0.001 0.001" />
    <mesh name="calf" file="../meshes/calf.stl" scale="0.001 0.001 0.001" />
    <mesh name="thigh" file="../meshes/thigh.stl" scale="0.001 0.001 0.001" />
  </asset>

  <worldbody>
    <body name="base" pos="0.00000000 0.00000000 0.44600000" quat="1 0 0 0" childclass="robot">
      <freejoint name="floating_base" />
      <geom name="base_visual" pos="0 0 0" quat="1.0 0.0 0.0 0.0" material="default_material" type="box" size="0.0005 0.0005 0.0005" class="visual" />
      <body name="wx250s/base_link" pos="0.03 0 0.057" quat="1.0 0.0 0.0 0.0">
        <inertial pos="-0.0380446000 0.0006138920 0.0193354000" quat="0.7071067811865476 0.0 0.0 0.7071067811865475" mass="0.538736" diaginertia="0.002115 0.0006921 0.002524" />
        <geom name="wx250s/base_link_collision" pos="0 0 0" quat="0.7071067811865476 0.0 0.0 0.7071067811865475" type="mesh" mesh="wx250s_1_base" class="collision" />
        <geom name="wx250s/base_link_visual" pos="0 0 0" quat="0.7071067811865476 0.0 0.0 0.7071067811865475" material="black" type="mesh" mesh="wx250s_1_base" class="visual" />
        <body name="wx250s/shoulder_link" pos="0 0 0.072" quat="1.0 0.0 0.0 0.0">
          <joint name="widow_waist" type="hinge" ref="0.0" class="motor" axis="0 0 1" />
          <inertial pos="0.0000223482 0.0000414609 0.0066287000" quat="0.7071067811865476 0.0 0.0 0.7071067811865475" mass="0.480879" diaginertia="0.000379 0.0005557 0.0005889" />
          <geom name="wx250s/shoulder_link_collision" pos="0 0 -0.003" quat="0.7071067811865476 0.0 0.0 0.7071067811865475" type="mesh" mesh="wx250s_2_shoulder" class="collision" />
          <geom name="wx250s/shoulder_link_visual" pos="0 0 -0.003" quat="0.7071067811865476 0.0 0.0 0.7071067811865475" material="black" type="mesh" mesh="wx250s_2_shoulder" class="visual" />
          <body name="wx250s/upper_arm_link" pos="0 0 0.03865" quat="1.0 0.0 0.0 0.0">
            <joint name="widow_shoulder" type="hinge" ref="0.0" class="motor" range="-1.8849555921538759 1.9896753472735358" axis="0 1 0" />
            <inertial pos="0.0171605000 0.0000002725 0.1913230000" quat="0.7071067811865476 0.0 0.0 0.7071067811865475" mass="0.430811" diaginertia="0.003463 0.003587 0.0004566" />
            <geom name="wx250s/upper_arm_link_collision" pos="0 0 0" quat="0.7071067811865476 0.0 0.0 0.7071067811865475" type="mesh" mesh="wx250s_3_upper_arm" class="collision" />
            <geom name="wx250s/upper_arm_link_visual" pos="0 0 0" quat="0.7071067811865476 0.0 0.0 0.7071067811865475" material="black" type="mesh" mesh="wx250s_3_upper_arm" class="visual" />
            <body name="wx250s/upper_forearm_link" pos="0.04975 0 0.25" quat="1.0 0.0 0.0 0.0">
              <joint name="widow_elbow" type="hinge" ref="0.0" class="motor" range="-2.1467549799530254 1.6057029118347832" axis="0 1 0" />
              <inertial pos="0.1079630000 0.0001158760 0" quat="1.0 0.0 0.0 0.0" mass="0.234589" diaginertia="3.971e-05 0.0008878 0.000888" />
              <geom name="wx250s/upper_forearm_link_collision" pos="0 0 0" quat="1.0 0.0 0.0 0.0" type="mesh" mesh="wx250s_4_upper_forearm" class="collision" />
              <geom name="wx250s/upper_forearm_link_visual" pos="0 0 0" quat="1.0 0.0 0.0 0.0" material="black" type="mesh" mesh="wx250s_4_upper_forearm" class="visual" />
              <body name="wx250s/lower_forearm_link" pos="0.175 0 0" quat="1.0 0.0 0.0 0.0">
                <joint name="widow_forearm_roll" type="hinge" ref="0.0" class="motor" range="-3.141582653589793 3.141582653589793" axis="1 0 0" />
                <inertial pos="0.0374395000 0.0052225200 0" quat="6.123233995736766e-17 1.0 0.0 0.0" mass="0.220991" diaginertia="6.369e-05 0.0001677 0.0001834" />
                <geom name="wx250s/lower_forearm_link_collision" pos="0 0 0" quat="6.123233995736766e-17 1.0 0.0 0.0" type="mesh" mesh="wx250s_5_lower_forearm" class="collision" />
                <geom name="wx250s/lower_forearm_link_visual" pos="0 0 0" quat="6.123233995736766e-17 1.0 0.0 0.0" material="black" type="mesh" mesh="wx250s_5_lower_forearm" class="visual" />
                <body name="wx250s/wrist_link" pos="0.075 0 0" quat="1.0 0.0 0.0 0.0">
                  <joint name="widow_wrist_angle" type="hinge" ref="0.0" class="motor" range="-1.7453292519943295 2.1467549799530254" axis="0 1 0" />
                  <inertial pos="0.0423600000 -0.0000106630 0.0105770000" quat="0.7071067811865476 0.0 0.0 0.7071067811865475" mass="0.084957" diaginertia="3.082e-05 2.822e-05 3.152e-05" />
                  <geom name="wx250s/wrist_link_collision" pos="0 0 0" quat="0.7071067811865476 0.0 0.0 0.7071067811865475" type="mesh" mesh="wx250s_6_wrist" class="collision" />
                  <geom name="wx250s/wrist_link_visual" pos="0 0 0" quat="0.7071067811865476 0.0 0.0 0.7071067811865475" material="black" type="mesh" mesh="wx250s_6_wrist" class="visual" />
                  <body name="wx250s/gripper_link" pos="0.065 0 0" quat="1.0 0.0 0.0 0.0">
                    <joint name="widow_wrist_rotate" type="hinge" ref="0.0" class="motor" range="-3.141582653589793 3.141582653589793" axis="1 0 0" />
                    <inertial pos="0.0216310000 0.0000002516 0.0114100000" quat="0.7071067811865476 0.0 0.0 0.7071067811865475" mass="0.072885" diaginertia="2.537e-05 1.836e-05 1.674e-05" />
                    <geom name="wx250s/gripper_link_collision" pos="-0.02 0 0" quat="0.7071067811865476 0.0 0.0 0.7071067811865475" type="mesh" mesh="wx250s_7_gripper" class="collision" />
                    <geom name="wx250s/gripper_link_visual" pos="-0.02 0 0" quat="0.7071067811865476 0.0 0.0 0.7071067811865475" material="black" type="mesh" mesh="wx250s_7_gripper" class="visual" />
                    <body name="wx250s/ee_arm_link" pos="0.043 0 0" quat="1.0 0.0 0.0 0.0">
                      <inertial pos="0 0 0" quat="1 0 0 0" mass="0.001" diaginertia="0.001 0.001 0.001" />
                      <body name="wx250s/gripper_prop_link" pos="0.0055 0 0" quat="1.0 0.0 0.0 0.0">
                        <inertial pos="0.0008460000 -0.0000016817 0.0000420000" quat="0.7071067811865476 0.0 0.0 0.7071067811865475" mass="0.00434" diaginertia="5.923e-07 1.1156e-06 5.743e-07" />
                        <geom name="wx250s/gripper_prop_link_collision" pos="-0.0685 0 0" quat="0.7071067811865476 0.0 0.0 0.7071067811865475" type="mesh" mesh="wx250s_8_gripper_prop" class="collision" />
                        <geom name="wx250s/gripper_prop_link_visual" pos="-0.0685 0 0" quat="0.7071067811865476 0.0 0.0 0.7071067811865475" material="black" type="mesh" mesh="wx250s_8_gripper_prop" class="visual" />
                      </body>
                      <body name="wx250s/gripper_bar_link" pos="0 0 0" quat="1.0 0.0 0.0 0.0">
                        <inertial pos="0.0096870000 0.0000008177 0.0049620000" quat="0.7071067811865476 0.0 0.0 0.7071067811865475" mass="0.034199" diaginertia="7.4125e-06 2.843e-05 2.86e-05" />
                        <geom name="wx250s/gripper_bar_link_collision" pos="-0.063 0 0" quat="0.7071067811865476 0.0 0.0 0.7071067811865475" type="mesh" mesh="wx250s_9_gripper_bar" class="collision" />
                        <geom name="wx250s/gripper_bar_link_visual" pos="-0.063 0 0" quat="0.7071067811865476 0.0 0.0 0.7071067811865475" material="black" type="mesh" mesh="wx250s_9_gripper_bar" class="visual" />
                        <body name="wx250s/fingers_link" pos="0.023 0 0" quat="1.0 0.0 0.0 0.0">
                          <inertial pos="0 0 0" quat="1 0 0 0" mass="0.001" diaginertia="0.001 0.001 0.001" />
                          <body name="wx250s/left_finger_link" pos="0 0 0" quat="1.0 0.0 0.0 0.0">
                            <joint name="widow_left_finger" type="slide" ref="0.0" class="motor" range="0.015 0.037" axis="0 1 0" />
                            <inertial pos="0.0138160000 0.0000000000 0.0000000000" quat="0.7071067811865475 1.232595164407831e-32 8.659560562354933e-17 -0.7071067811865476" mass="0.016246" diaginertia="4.731e-06 1.5506e-06 3.7467e-06" />
                            <geom name="wx250s/left_finger_link_collision" pos="0 0.005 0" quat="3.749399456654644e-33 6.123233995736766e-17 6.123233995736766e-17 -1.0" type="mesh" mesh="wx250s_10_gripper_finger" class="collision" />
                            <geom name="wx250s/left_finger_link_visual" pos="0 0.005 0" quat="3.749399456654644e-33 6.123233995736766e-17 6.123233995736766e-17 -1.0" material="black" type="mesh" mesh="wx250s_10_gripper_finger" class="visual" />
                          </body>
                          <body name="wx250s/right_finger_link" pos="0 0 0" quat="1.0 0.0 0.0 0.0">
                            <joint name="widow_right_finger" type="slide" ref="0.0" class="motor" range="-0.037 -0.015" axis="0 1 0" />
                            <inertial pos="0.0138160000 0.0000000000  0.0000000000" quat="4.329780281177467e-17 -0.7071067811865475 0.7071067811865476 4.329780281177466e-17" mass="0.016246" diaginertia="4.731e-06 1.5506e-06 3.7467e-06" />
                            <geom name="wx250s/right_finger_link_collision" pos="0 -0.005 0" quat="6.123233995736766e-17 0.0 1.0 0.0" type="mesh" mesh="wx250s_10_gripper_finger" class="collision" />
                            <geom name="wx250s/right_finger_link_visual" pos="0 -0.005 0" quat="6.123233995736766e-17 0.0 1.0 0.0" material="black" type="mesh" mesh="wx250s_10_gripper_finger" class="visual" />
                          </body>
                          <body name="wx250s/ee_gripper_link" pos="0.027575 0 0" quat="1.0 0.0 0.0 0.0">
                            <inertial pos="0 0 0" quat="1 0 0 0" mass="0.001" diaginertia="0.001 0.001 0.001" />
                          </body>
                        </body>
                      </body>
                    </body>
                  </body>
                </body>
              </body>
            </body>
          </body>
        </body>
      </body>
      <body name="trunk" pos="0 0 0" quat="1.0 0.0 0.0 0.0">
        <inertial pos="0.0223 0.002 -0.0005" quat="1.0 0.0 0.0 0.0" mass="5.204" diaginertia="0.0168352186 0.0656071082 0.0742720659" />
        <geom name="trunk_collision" pos="0 0 0" quat="1.0 0.0 0.0 0.0" type="box" size="0.1881 0.04675 0.057" class="collision" />
        <geom name="trunk_visual" pos="0 0 0" quat="1.0 0.0 0.0 0.0" material="silver" type="mesh" mesh="trunk" class="visual" />
        <body name="imu_link" pos="-0.01592 -0.06659 -0.00617" quat="1.0 0.0 0.0 0.0">
          <inertial pos="0 0 0" quat="1.0 0.0 0.0 0.0" mass="0.001" diaginertia="0.0001 0.0001 0.0001" />
          <geom name="imu_link_collision" pos="0 0 0" quat="1.0 0.0 0.0 0.0" type="box" size="0.0005 0.0005 0.0005" class="collision" />
          <geom name="imu_link_visual" pos="0 0 0" quat="1.0 0.0 0.0 0.0" material="default_material" type="box" size="0.0005 0.0005 0.0005" class="visual" />
        </body>
        <body name="FR_hip" pos="0.1881 -0.04675 0" quat="1.0 0.0 0.0 0.0">
          <joint name="FR_hip_joint" type="hinge" ref="0.0" class="motor" range="-1.0471975512 1.0471975512" axis="1 0 0" />
          <inertial pos="-0.00541 0.00074 6e-06" quat="1.0 0.0 0.0 0.0" mass="0.591" diaginertia="0.000374268192 0.000635923669 0.000457647394" />
          <geom name="FR_hip_visual" pos="0 0 0" quat="-1.0341155355510722e-13 1.0 0.0 -0.0" material="silver" type="mesh" mesh="hip" class="visual" />
          <body name="FR_thigh_shoulder" pos="0 -0.08 0" quat="1.0 0.0 0.0 0.0" />
          <body name="FR_thigh" pos="0 -0.08 0" quat="1.0 0.0 0.0 0.0">
            <joint name="FR_thigh_joint" type="hinge" ref="0.0" class="motor" range="-0.663225115758 2.96705972839" axis="0 1 0" />
            <inertial pos="-0.003468 0.018947 -0.032736" quat="1.0 0.0 0.0 0.0" mass="0.92" diaginertia="0.005851561134 0.005596155105 0.00107157026" />
            <geom name="FR_thigh_collision" pos="0 0 -0.1065" quat="0.7071067811882787 0.0 0.7071067811848163 0.0" type="box" size="0.1065 0.01225 0.017" class="collision" />
            <geom name="FR_thigh_visual" pos="0 0 0" quat="1.0 0.0 0.0 0.0" material="silver" type="mesh" mesh="thigh_mirror" class="visual" />
            <body name="FR_calf" pos="0 0 -0.213" quat="1.0 0.0 0.0 0.0">
              <joint name="FR_calf_joint" type="hinge" ref="0.0" class="motor" range="-2.72271363311 -0.837758040957" axis="0 1 0" />
              <inertial pos="0.006286 0.001307 -0.122269" quat="1.0 0.0 0.0 0.0" mass="0.131" diaginertia="0.002939186297 0.00295576935 3.0273372e-05" />
              <geom name="FR_calf_collision" pos="0 0 -0.1065" quat="0.7071067811882787 0.0 0.7071067811848163 0.0" type="box" size="0.1065 0.008 0.008" class="collision" />
              <geom name="FR_calf_visual" pos="0 0 0" quat="1.0 0.0 0.0 0.0" material="silver" type="mesh" mesh="calf" class="visual" />
              <body name="FR_foot" pos="0 0 -0.213" quat="1.0 0.0 0.0 0.0">
                <inertial pos="0 0 0" quat="1 0 0 0" mass="0.06" diaginertia="9.6e-06 9.6e-06 9.6e-06" />
                <geom name="FR_foot_collision" pos="0 0 0" quat="1.0 0.0 0.0 0.0" type="sphere" size="0.02" class="collision" />
                <geom name="FR_foot_visual" pos="0 0 0" quat="1.0 0.0 0.0 0.0" material="black" type="sphere" size="0.01" class="visual" />
              </body>
            </body>
          </body>
        </body>
        <body name="FL_hip" pos="0.1881 0.04675 0" quat="1.0 0.0 0.0 0.0">
          <joint name="FL_hip_joint" type="hinge" ref="0.0" class="motor" range="-1.0471975512 1.0471975512" axis="1 0 0" />
          <inertial pos="-0.00541 -0.00074 6e-06" quat="1.0 0.0 0.0 0.0" mass="0.591" diaginertia="0.000374268192 0.000635923669 0.000457647394" />
          <geom name="FL_hip_visual" pos="0 0 0" quat="1.0 0.0 0.0 0.0" material="silver" type="mesh" mesh="hip" class="visual" />
          <body name="FL_thigh_shoulder" pos="0 0.08 0" quat="1.0 0.0 0.0 0.0" />
          <body name="FL_thigh" pos="0 0.08 0" quat="1.0 0.0 0.0 0.0">
            <joint name="FL_thigh_joint" type="hinge" ref="0.0" class="motor" range="-0.663225115758 2.96705972839" axis="0 1 0" />
            <inertial pos="-0.003468 -0.018947 -0.032736" quat="1.0 0.0 0.0 0.0" mass="0.92" diaginertia="0.005851561134 0.005596155105 0.00107157026" />
            <geom name="FL_thigh_collision" pos="0 0 -0.1065" quat="0.7071067811882787 0.0 0.7071067811848163 0.0" type="box" size="0.1065 0.01225 0.017" class="collision" />
            <geom name="FL_thigh_visual" pos="0 0 0" quat="1.0 0.0 0.0 0.0" material="silver" type="mesh" mesh="thigh" class="visual" />
            <body name="FL_calf" pos="0 0 -0.213" quat="1.0 0.0 0.0 0.0">
              <joint name="FL_calf_joint" type="hinge" ref="0.0" class="motor" range="-2.72271363311 -0.837758040957" axis="0 1 0" />
              <inertial pos="0.006286 0.001307 -0.122269" quat="1.0 0.0 0.0 0.0" mass="0.131" diaginertia="0.002939186297 0.00295576935 3.0273372e-05" />
              <geom name="FL_calf_collision" pos="0 0 -0.1065" quat="0.7071067811882787 0.0 0.7071067811848163 0.0" type="box" size="0.1065 0.008 0.008" class="collision" />
              <geom name="FL_calf_visual" pos="0 0 0" quat="1.0 0.0 0.0 0.0" material="silver" type="mesh" mesh="calf" class="visual" />
              <body name="FL_foot" pos="0 0 -0.213" quat="1.0 0.0 0.0 0.0">
                <inertial pos="0 0 0" quat="1 0 0 0" mass="0.06" diaginertia="9.6e-06 9.6e-06 9.6e-06" />
                <geom name="FL_foot_collision" pos="0 0 0" quat="1.0 0.0 0.0 0.0" type="sphere" size="0.02" class="collision" />
                <geom name="FL_foot_visual" pos="0 0 0" quat="1.0 0.0 0.0 0.0" material="black" type="sphere" size="0.01" class="visual" />
              </body>
            </body>
          </body>
        </body>
        <body name="RR_hip" pos="-0.1881 -0.04675 0" quat="1.0 0.0 0.0 0.0">
          <joint name="RR_hip_joint" type="hinge" ref="0.0" class="motor" range="-1.0471975512 1.0471975512" axis="1 0 0" />
          <inertial pos="0.00541 0.00074 6e-06" quat="1.0 0.0 0.0 0.0" mass="0.591" diaginertia="0.000374268192 0.000635923669 0.000457647394" />
          <geom name="RR_hip_visual" pos="0 0 0" quat="1.0693949408680808e-26 -1.0341155355510722e-13 -1.0341155355510722e-13 -1.0" material="silver" type="mesh" mesh="hip" class="visual" />
          <body name="RR_thigh_shoulder" pos="0 -0.08 0" quat="1.0 0.0 0.0 0.0" />
          <body name="RR_thigh" pos="0 -0.08 0" quat="1.0 0.0 0.0 0.0">
            <joint name="RR_thigh_joint" type="hinge" ref="0.0" class="motor" range="-0.663225115758 2.96705972839" axis="0 1 0" />
            <inertial pos="-0.003468 0.018947 -0.032736" quat="1.0 0.0 0.0 0.0" mass="0.92" diaginertia="0.005851561134 0.005596155105 0.00107157026" />
            <geom name="RR_thigh_collision" pos="0 0 -0.1065" quat="0.7071067811882787 0.0 0.7071067811848163 0.0" type="box" size="0.1065 0.01225 0.017" class="collision" />
            <geom name="RR_thigh_visual" pos="0 0 0" quat="1.0 0.0 0.0 0.0" material="silver" type="mesh" mesh="thigh_mirror" class="visual" />
            <body name="RR_calf" pos="0 0 -0.213" quat="1.0 0.0 0.0 0.0">
              <joint name="RR_calf_joint" type="hinge" ref="0.0" class="motor" range="-2.72271363311 -0.837758040957" axis="0 1 0" />
              <inertial pos="0.006286 0.001307 -0.122269" quat="1.0 0.0 0.0 0.0" mass="0.131" diaginertia="0.002939186297 0.00295576935 3.0273372e-05" />
              <geom name="RR_calf_collision" pos="0 0 -0.1065" quat="0.7071067811882787 0.0 0.7071067811848163 0.0" type="box" size="0.1065 0.008 0.008" class="collision" />
              <geom name="RR_calf_visual" pos="0 0 0" quat="1.0 0.0 0.0 0.0" material="silver" type="mesh" mesh="calf" class="visual" />
              <body name="RR_foot" pos="0 0 -0.213" quat="1.0 0.0 0.0 0.0">
                <inertial pos="0 0 0" quat="1 0 0 0" mass="0.06" diaginertia="9.6e-06 9.6e-06 9.6e-06" />
                <geom name="RR_foot_collision" pos="0 0 0" quat="1.0 0.0 0.0 0.0" type="sphere" size="0.02" class="collision" />
                <geom name="RR_foot_visual" pos="0 0 0" quat="1.0 0.0 0.0 0.0" material="black" type="sphere" size="0.01" class="visual" />
              </body>
            </body>
          </body>
        </body>
        <body name="RL_hip" pos="-0.1881 0.04675 0" quat="1.0 0.0 0.0 0.0">
          <joint name="RL_hip_joint" type="hinge" ref="0.0" class="motor" range="-1.0471975512 1.0471975512" axis="1 0 0" />
          <inertial pos="0.00541 -0.00074 6e-06" quat="1.0 0.0 0.0 0.0" mass="0.591" diaginertia="0.000374268192 0.000635923669 0.000457647394" />
          <geom name="RL_hip_visual" pos="0 0 0" quat="-1.0341155355510722e-13 -0.0 1.0 -0.0" material="silver" type="mesh" mesh="hip" class="visual" />
          <body name="RL_thigh_shoulder" pos="0 0.08 0" quat="1.0 0.0 0.0 0.0" />
          <body name="RL_thigh" pos="0 0.08 0" quat="1.0 0.0 0.0 0.0">
            <joint name="RL_thigh_joint" type="hinge" ref="0.0" class="motor" range="-0.663225115758 2.96705972839" axis="0 1 0" />
            <inertial pos="-0.003468 -0.018947 -0.032736" quat="1.0 0.0 0.0 0.0" mass="0.92" diaginertia="0.005851561134 0.005596155105 0.00107157026" />
            <geom name="RL_thigh_collision" pos="0 0 -0.1065" quat="0.7071067811882787 0.0 0.7071067811848163 0.0" type="box" size="0.1065 0.01225 0.017" class="collision" />
            <geom name="RL_thigh_visual" pos="0 0 0" quat="1.0 0.0 0.0 0.0" material="silver" type="mesh" mesh="thigh" class="visual" />
            <body name="RL_calf" pos="0 0 -0.213" quat="1.0 0.0 0.0 0.0">
              <joint name="RL_calf_joint" type="hinge" ref="0.0" class="motor" range="-2.72271363311 -0.837758040957" axis="0 1 0" />
              <inertial pos="0.006286 0.001307 -0.122269" quat="1.0 0.0 0.0 0.0" mass="0.131" diaginertia="0.002939186297 0.00295576935 3.0273372e-05" />
              <geom name="RL_calf_collision" pos="0 0 -0.1065" quat="0.7071067811882787 0.0 0.7071067811848163 0.0" type="box" size="0.1065 0.008 0.008" class="collision" />
              <geom name="RL_calf_visual" pos="0 0 0" quat="1.0 0.0 0.0 0.0" material="silver" type="mesh" mesh="calf" class="visual" />
              <body name="RL_foot" pos="0 0 -0.213" quat="1.0 0.0 0.0 0.0">
                <inertial pos="0 0 0" quat="1 0 0 0" mass="0.06" diaginertia="9.6e-06 9.6e-06 9.6e-06" />
                <geom name="RL_foot_collision" pos="0 0 0" quat="1.0 0.0 0.0 0.0" type="sphere" size="0.02" class="collision" />
                <geom name="RL_foot_visual" pos="0 0 0" quat="1.0 0.0 0.0 0.0" material="black" type="sphere" size="0.01" class="visual" />
              </body>
            </body>
          </body>
        </body>
      </body>
      <site name="base_site" pos="0 0 0" quat="1 0 0 0" />
      <camera name="front_camera" mode="track" fovy="90.0" quat="4.329780281177467e-17 4.329780281177466e-17 0.7071067811865475 0.7071067811865476" pos="0.0 2.0 0.5" />
      <camera name="side_camera" mode="track" fovy="90.0" quat="-0.5 -0.4999999999999999 0.5 0.5000000000000001" pos="-2.0 0.0 0.5" />
    </body>
  </worldbody>

  <actuator>
    <motor name="widow_waist_ctrl" joint="widow_waist" class="motor" />
    <motor name="widow_shoulder_ctrl" joint="widow_shoulder" class="motor" />
    <motor name="widow_elbow_ctrl" joint="widow_elbow" class="motor" />
    <motor name="widow_forearm_roll_ctrl" joint="widow_forearm_roll" class="motor" />
    <motor name="widow_wrist_angle_ctrl" joint="widow_wrist_angle" class="motor" />
    <motor name="widow_wrist_rotate_ctrl" joint="widow_wrist_rotate" class="motor" />
    <motor name="widow_left_finger_ctrl" joint="widow_left_finger" class="motor" />
    <motor name="widow_right_finger_ctrl" joint="widow_right_finger" class="motor" />
    <motor name="FR_hip_joint_ctrl" joint="FR_hip_joint" class="motor" />
    <motor name="FR_thigh_joint_ctrl" joint="FR_thigh_joint" class="motor" />
    <motor name="FR_calf_joint_ctrl" joint="FR_calf_joint" class="motor" />
    <motor name="FL_hip_joint_ctrl" joint="FL_hip_joint" class="motor" />
    <motor name="FL_thigh_joint_ctrl" joint="FL_thigh_joint" class="motor" />
    <motor name="FL_calf_joint_ctrl" joint="FL_calf_joint" class="motor" />
    <motor name="RR_hip_joint_ctrl" joint="RR_hip_joint" class="motor" />
    <motor name="RR_thigh_joint_ctrl" joint="RR_thigh_joint" class="motor" />
    <motor name="RR_calf_joint_ctrl" joint="RR_calf_joint" class="motor" />
    <motor name="RL_hip_joint_ctrl" joint="RL_hip_joint" class="motor" />
    <motor name="RL_thigh_joint_ctrl" joint="RL_thigh_joint" class="motor" />
    <motor name="RL_calf_joint_ctrl" joint="RL_calf_joint" class="motor" />
  </actuator>

  <contact>
    <exclude body1="wx250s/base_link" body2="wx250s/shoulder_link" />
    <exclude body1="wx250s/shoulder_link" body2="wx250s/upper_arm_link" />
    <exclude body1="wx250s/upper_arm_link" body2="wx250s/upper_forearm_link" />
    <exclude body1="wx250s/upper_forearm_link" body2="wx250s/lower_forearm_link" />
    <exclude body1="wx250s/lower_forearm_link" body2="wx250s/wrist_link" />
    <exclude body1="wx250s/wrist_link" body2="wx250s/gripper_link" />
    <exclude body1="trunk" body2="imu_link" />
    <exclude body1="FR_thigh" body2="FR_calf" />
    <exclude body1="FR_calf" body2="FR_foot" />
    <exclude body1="FL_thigh" body2="FL_calf" />
    <exclude body1="FL_calf" body2="FL_foot" />
    <exclude body1="RR_thigh" body2="RR_calf" />
    <exclude body1="RR_calf" body2="RR_foot" />
    <exclude body1="RL_thigh" body2="RL_calf" />
    <exclude body1="RL_calf" body2="RL_foot" />
  </contact>

  <sensor>
    <framepos name="base_site_pos" objtype="site" objname="base_site" />
    <framequat name="base_site_quat" objtype="site" objname="base_site" />
    <framelinvel name="base_site_linvel" objtype="site" objname="base_site" />
    <frameangvel name="base_site_angvel" objtype="site" objname="base_site" />
    <velocimeter name="base_site_vel" site="base_site" />
  </sensor>
</mujoco>